<?xml version="1.0" encoding="UTF-8"?>
<testng-results skipped="0" failed="1" total="1" passed="0">
  <reporter-output>
  </reporter-output>
  <suite name="Suite" duration-ms="127" started-at="2019-12-21T18:54:33Z" finished-at="2019-12-21T18:54:33Z">
    <groups>
    </groups>
    <test name="Test" duration-ms="127" started-at="2019-12-21T18:54:33Z" finished-at="2019-12-21T18:54:33Z">
      <class name="Exposure.RestAssured.addReminderTests">
        <test-method status="FAIL" signature="initialiseDB()[pri:0, instance:Exposure.RestAssured.addReminderTests@371a67ec]" name="initialiseDB" is-config="true" duration-ms="0" started-at="2019-12-21T18:54:11Z" finished-at="2019-12-21T18:54:11Z">
          <exception class="java.sql.SQLRecoverableException">
            <message>
              <![CDATA[IO Error: The Network Adapter could not establish the connection]]>
            </message>
            <full-stacktrace>
              <![CDATA[java.sql.SQLRecoverableException: IO Error: The Network Adapter could not establish the connection
	at oracle.jdbc.driver.T4CConnection.logon(T4CConnection.java:419)
	at oracle.jdbc.driver.PhysicalConnection.<init>(PhysicalConnection.java:536)
	at oracle.jdbc.driver.T4CConnection.<init>(T4CConnection.java:228)
	at oracle.jdbc.driver.T4CDriverExtension.getConnection(T4CDriverExtension.java:32)
	at oracle.jdbc.driver.OracleDriver.connect(OracleDriver.java:521)
	at java.sql.DriverManager.getConnection(Unknown Source)
	at java.sql.DriverManager.getConnection(Unknown Source)
	at dbConnection.DataBaseConnection.ComicConnection(DataBaseConnection.java:36)
	at dbConnection.DataBaseConnection.<init>(DataBaseConnection.java:29)
	at base.Testbase.initialiseDB(Testbase.java:33)
	at sun.reflect.NativeMethodAccessorImpl.invoke0(Native Method)
	at sun.reflect.NativeMethodAccessorImpl.invoke(Unknown Source)
	at sun.reflect.DelegatingMethodAccessorImpl.invoke(Unknown Source)
	at java.lang.reflect.Method.invoke(Unknown Source)
	at org.testng.internal.MethodInvocationHelper.invokeMethod(MethodInvocationHelper.java:80)
	at org.testng.internal.Invoker.invokeConfigurationMethod(Invoker.java:551)
	at org.testng.internal.Invoker.invokeConfigurations(Invoker.java:213)
	at org.testng.internal.Invoker.invokeConfigurations(Invoker.java:138)
	at org.testng.SuiteRunner.privateRun(SuiteRunner.java:277)
	at org.testng.SuiteRunner.run(SuiteRunner.java:240)
	at org.testng.SuiteRunnerWorker.runSuite(SuiteRunnerWorker.java:53)
	at org.testng.SuiteRunnerWorker.run(SuiteRunnerWorker.java:87)
	at org.testng.TestNG.runSuitesSequentially(TestNG.java:1188)
	at org.testng.TestNG.runSuitesLocally(TestNG.java:1113)
	at org.testng.TestNG.run(TestNG.java:1025)
	at org.testng.remote.AbstractRemoteTestNG.run(AbstractRemoteTestNG.java:114)
	at org.testng.remote.RemoteTestNG.initAndRun(RemoteTestNG.java:251)
	at org.testng.remote.RemoteTestNG.main(RemoteTestNG.java:77)
Caused by: oracle.net.ns.NetException: The Network Adapter could not establish the connection
	at oracle.net.nt.ConnStrategy.execute(ConnStrategy.java:375)
	at oracle.net.resolver.AddrResolution.resolveAndExecute(AddrResolution.java:422)
	at oracle.net.ns.NSProtocol.establishConnection(NSProtocol.java:678)
	at oracle.net.ns.NSProtocol.connect(NSProtocol.java:238)
	at oracle.jdbc.driver.T4CConnection.connect(T4CConnection.java:1054)
	at oracle.jdbc.driver.T4CConnection.logon(T4CConnection.java:308)
	... 27 more
Caused by: java.net.ConnectException: Connection timed out: connect
	at java.net.DualStackPlainSocketImpl.waitForConnect(Native Method)
	at java.net.DualStackPlainSocketImpl.socketConnect(Unknown Source)
	at java.net.AbstractPlainSocketImpl.doConnect(Unknown Source)
	at java.net.AbstractPlainSocketImpl.connectToAddress(Unknown Source)
	at java.net.AbstractPlainSocketImpl.connect(Unknown Source)
	at java.net.PlainSocketImpl.connect(Unknown Source)
	at java.net.SocksSocketImpl.connect(Unknown Source)
	at java.net.Socket.connect(Unknown Source)
	at oracle.net.nt.TcpNTAdapter.connect(TcpNTAdapter.java:209)
	at oracle.net.nt.ConnOption.connect(ConnOption.java:123)
	at oracle.net.nt.ConnStrategy.execute(ConnStrategy.java:353)
	... 32 more
]]>
            </full-stacktrace>
          </exception> <!-- java.sql.SQLRecoverableException -->
        </test-method> <!-- initialiseDB -->
        <test-method status="FAIL" signature="addReminderInsertion_BEP14470001()[pri:0, instance:Exposure.RestAssured.addReminderTests@371a67ec]" name="addReminderInsertion_BEP14470001" duration-ms="16" started-at="2019-12-21T18:54:33Z" finished-at="2019-12-21T18:54:33Z">
          <exception class="java.lang.NullPointerException">
            <full-stacktrace>
              <![CDATA[java.lang.NullPointerException
	at java.util.regex.Matcher.getTextLength(Unknown Source)
	at java.util.regex.Matcher.reset(Unknown Source)
	at java.util.regex.Matcher.<init>(Unknown Source)
	at java.util.regex.Pattern.matcher(Unknown Source)
	at com.aventstack.extentreports.utils.ExceptionUtil.getExceptionHeadline(ExceptionUtil.java:25)
	at com.aventstack.extentreports.ExtentTest.log(ExtentTest.java:399)
	at com.aventstack.extentreports.ExtentTest.skip(ExtentTest.java:943)
	at com.aventstack.extentreports.ExtentTest.skip(ExtentTest.java:955)
	at listeners.TestListener.onTestSkipped(TestListener.java:52)
	at org.testng.internal.Invoker.runTestListeners(Invoker.java:1875)
	at org.testng.internal.Invoker.runTestListeners(Invoker.java:1867)
	at org.testng.internal.Invoker.invokeMethod(Invoker.java:775)
	at org.testng.internal.Invoker.invokeTestMethod(Invoker.java:894)
	at org.testng.internal.Invoker.invokeTestMethods(Invoker.java:1219)
	at org.testng.internal.TestMethodWorker.invokeTestMethods(TestMethodWorker.java:127)
	at org.testng.internal.TestMethodWorker.run(TestMethodWorker.java:111)
	at org.testng.TestRunner.privateRun(TestRunner.java:768)
	at org.testng.TestRunner.run(TestRunner.java:617)
	at org.testng.SuiteRunner.runTest(SuiteRunner.java:334)
	at org.testng.SuiteRunner.runSequentially(SuiteRunner.java:329)
	at org.testng.SuiteRunner.privateRun(SuiteRunner.java:291)
	at org.testng.SuiteRunner.run(SuiteRunner.java:240)
	at org.testng.SuiteRunnerWorker.runSuite(SuiteRunnerWorker.java:53)
	at org.testng.SuiteRunnerWorker.run(SuiteRunnerWorker.java:87)
	at org.testng.TestNG.runSuitesSequentially(TestNG.java:1188)
	at org.testng.TestNG.runSuitesLocally(TestNG.java:1113)
	at org.testng.TestNG.run(TestNG.java:1025)
	at org.testng.remote.AbstractRemoteTestNG.run(AbstractRemoteTestNG.java:114)
	at org.testng.remote.RemoteTestNG.initAndRun(RemoteTestNG.java:251)
	at org.testng.remote.RemoteTestNG.main(RemoteTestNG.java:77)
]]>
            </full-stacktrace>
          </exception> <!-- java.lang.NullPointerException -->
        </test-method> <!-- addReminderInsertion_BEP14470001 -->
        <test-method status="SKIP" signature="closeConnection()[pri:0, instance:Exposure.RestAssured.addReminderTests@371a67ec]" name="closeConnection" is-config="true" duration-ms="0" started-at="2019-12-21T18:54:34Z" finished-at="2019-12-21T18:54:34Z">
        </test-method> <!-- closeConnection -->
      </class> <!-- Exposure.RestAssured.addReminderTests -->
    </test> <!-- Test -->
  </suite> <!-- Suite -->
</testng-results>
